2025-04-30 11:23:04 - INFO - Starting Federated Learning Simulation: dataset type: iid, dataset name: mnist, strategy: FedAvg(accept_failures=True), rounds: 50, clients: 20
2025-04-30 11:23:04 - WARNING - DEPRECATED FEATURE: flwr.simulation.start_simulation() is deprecated.
	Instead, use the `flwr run` CLI command to start a local simulation in your Flower app, as shown for example below:

		$ flwr new  # Create a new Flower app from a template

		$ flwr run  # Run the Flower app in Simulation Mode

	Using `start_simulation()` is deprecated.

            This is a deprecated feature. It will be removed
            entirely in future versions of Flower.
        
2025-04-30 11:23:04 - INFO - Starting Flower simulation, config: num_rounds=50, no round_timeout
2025-04-30 11:23:07 - INFO - Flower VCE: Ray initialized with resources: {'accelerator_type:G': 1.0, 'node:__internal_head__': 1.0, 'CPU': 24.0, 'object_store_memory': 6283672780.0, 'node:127.0.0.1': 1.0, 'memory': 12567345563.0, 'GPU': 1.0}
2025-04-30 11:23:07 - INFO - Optimize your simulation with Flower VCE: https://flower.ai/docs/framework/how-to-run-simulations.html
2025-04-30 11:23:07 - INFO - No `client_resources` specified. Using minimal resources for clients.
2025-04-30 11:23:07 - INFO - Flower VCE: Resources for each Virtual Client: {'num_cpus': 1, 'num_gpus': 0.0}
2025-04-30 11:23:07 - INFO - Flower VCE: Creating VirtualClientEngineActorPool with 24 actors
2025-04-30 11:23:07 - INFO - [INIT]
2025-04-30 11:23:07 - INFO - Requesting initial parameters from one random client
2025-04-30 11:23:10 - INFO - Received initial parameters from one random client
2025-04-30 11:23:10 - INFO - Starting evaluation of initial global parameters
2025-04-30 11:23:14 - INFO - initial parameters (loss, other metrics): 0.07382761383056641, {'central_global_loss': 0.07382761383056641, 'central_global_accuracy': 0.098, 'central_clean_loss': 0.07206743800640106, 'central_clean_accuracy': 0.1215, 'central_malicious_loss': 0.07206743800640106, 'central_malicious_accuracy': 0.1215}
2025-04-30 11:23:14 - INFO - 
2025-04-30 11:23:14 - INFO - [ROUND 1]
2025-04-30 11:23:14 - INFO - configure_fit: strategy sampled 20 clients (out of 20)
2025-04-30 11:23:18 - ERROR - Traceback (most recent call last):
  File "C:\RL Adaptive Model Poisoning Attacks in FL\.venv\lib\site-packages\flwr\simulation\ray_transport\ray_client_proxy.py", line 95, in _submit_job
    out_mssg, updated_context = self.actor_pool.get_client_result(
  File "C:\RL Adaptive Model Poisoning Attacks in FL\.venv\lib\site-packages\flwr\simulation\ray_transport\ray_actor.py", line 401, in get_client_result
    return self._fetch_future_result(cid)
  File "C:\RL Adaptive Model Poisoning Attacks in FL\.venv\lib\site-packages\flwr\simulation\ray_transport\ray_actor.py", line 282, in _fetch_future_result
    res_cid, out_mssg, updated_context = ray.get(
  File "C:\RL Adaptive Model Poisoning Attacks in FL\.venv\lib\site-packages\ray\_private\auto_init_hook.py", line 21, in auto_init_wrapper
    return fn(*args, **kwargs)
  File "C:\RL Adaptive Model Poisoning Attacks in FL\.venv\lib\site-packages\ray\_private\client_mode_hook.py", line 103, in wrapper
    return func(*args, **kwargs)
  File "C:\RL Adaptive Model Poisoning Attacks in FL\.venv\lib\site-packages\ray\_private\worker.py", line 2639, in get
    values, debugger_breakpoint = worker.get_objects(object_refs, timeout=timeout)
  File "C:\RL Adaptive Model Poisoning Attacks in FL\.venv\lib\site-packages\ray\_private\worker.py", line 864, in get_objects
    raise value.as_instanceof_cause()
ray.exceptions.RayTaskError(ClientAppException): [36mray::ClientAppActor.run()[39m (pid=13392, ip=127.0.0.1, actor_id=41bbf42d74299670ad7431d601000000, repr=<flwr.simulation.ray_transport.ray_actor.ClientAppActor object at 0x000002D18018C970>)
  File "C:\RL Adaptive Model Poisoning Attacks in FL\.venv\lib\site-packages\flwr\client\client_app.py", line 144, in __call__
    return self._call(message, context)
  File "C:\RL Adaptive Model Poisoning Attacks in FL\.venv\lib\site-packages\flwr\client\client_app.py", line 128, in ffn
    out_message = handle_legacy_message_from_msgtype(
  File "C:\RL Adaptive Model Poisoning Attacks in FL\.venv\lib\site-packages\flwr\client\message_handler\message_handler.py", line 96, in handle_legacy_message_from_msgtype
    client = client_fn(context)
  File "C:\RL Adaptive Model Poisoning Attacks in FL\.venv\lib\site-packages\flwr\client\client_app.py", line 72, in adaptor_fn
    return client_fn(str(cid))  # type: ignore
  File "C:\RL Adaptive Model Poisoning Attacks in FL\federated_learning\server.py", line 154, in client_fn
    return poisoned_client_fn(
  File "C:\RL Adaptive Model Poisoning Attacks in FL\federated_learning\poisoned_client.py", line 150, in poisoned_client_fn
    return Poisoned_AdaptiveClient(
  File "C:\RL Adaptive Model Poisoning Attacks in FL\federated_learning\poisoned_client.py", line 37, in __init__
    self.poisoner = RLAdaptiveModelPoisoning()
  File "C:\RL Adaptive Model Poisoning Attacks in FL\federated_learning\attacks\deep_rl_adaptive_model_poisoning.py", line 7, in __init__
    self.model = DQN.load(agent_path)
  File "C:\RL Adaptive Model Poisoning Attacks in FL\.venv\lib\site-packages\stable_baselines3\common\base_class.py", line 681, in load
    data, params, pytorch_variables = load_from_zip_file(
  File "C:\RL Adaptive Model Poisoning Attacks in FL\.venv\lib\site-packages\stable_baselines3\common\save_util.py", line 403, in load_from_zip_file
    file = open_path(load_path, "r", verbose=verbose, suffix="zip")
  File "C:\Program Files\WindowsApps\PythonSoftwareFoundation.Python.3.9_3.9.3568.0_x64__qbz5n2kfra8p0\lib\functools.py", line 888, in wrapper
    return dispatch(args[0].__class__)(*args, **kw)
  File "C:\RL Adaptive Model Poisoning Attacks in FL\.venv\lib\site-packages\stable_baselines3\common\save_util.py", line 240, in open_path_str
    return open_path_pathlib(pathlib.Path(path), mode, verbose, suffix)
  File "C:\RL Adaptive Model Poisoning Attacks in FL\.venv\lib\site-packages\stable_baselines3\common\save_util.py", line 291, in open_path_pathlib
    return open_path_pathlib(path, mode, verbose, suffix)
  File "C:\RL Adaptive Model Poisoning Attacks in FL\.venv\lib\site-packages\stable_baselines3\common\save_util.py", line 272, in open_path_pathlib
    raise error
  File "C:\RL Adaptive Model Poisoning Attacks in FL\.venv\lib\site-packages\stable_baselines3\common\save_util.py", line 264, in open_path_pathlib
    return open_path(path.open("rb"), mode, verbose, suffix)
  File "C:\Program Files\WindowsApps\PythonSoftwareFoundation.Python.3.9_3.9.3568.0_x64__qbz5n2kfra8p0\lib\pathlib.py", line 1252, in open
    return io.open(self, mode, buffering, encoding, errors, newline,
  File "C:\Program Files\WindowsApps\PythonSoftwareFoundation.Python.3.9_3.9.3568.0_x64__qbz5n2kfra8p0\lib\pathlib.py", line 1120, in _opener
    return self._accessor.open(self, flags, mode)
FileNotFoundError: [Errno 2] No such file or directory: 'rl_poisoning_agent.zip'

The above exception was the direct cause of the following exception:

[36mray::ClientAppActor.run()[39m (pid=13392, ip=127.0.0.1, actor_id=41bbf42d74299670ad7431d601000000, repr=<flwr.simulation.ray_transport.ray_actor.ClientAppActor object at 0x000002D18018C970>)
  File "python\ray\_raylet.pyx", line 1890, in ray._raylet.execute_task
  File "python\ray\_raylet.pyx", line 1991, in ray._raylet.execute_task
  File "python\ray\_raylet.pyx", line 1896, in ray._raylet.execute_task
  File "python\ray\_raylet.pyx", line 1837, in ray._raylet.execute_task.function_executor
  File "C:\RL Adaptive Model Poisoning Attacks in FL\.venv\lib\site-packages\ray\_private\function_manager.py", line 691, in actor_method_executor
    return method(__ray_actor, *args, **kwargs)
  File "C:\RL Adaptive Model Poisoning Attacks in FL\.venv\lib\site-packages\ray\util\tracing\tracing_helper.py", line 467, in _resume_span
    return method(self, *_args, **_kwargs)
  File "C:\RL Adaptive Model Poisoning Attacks in FL\.venv\lib\site-packages\flwr\simulation\ray_transport\ray_actor.py", line 64, in run
    raise ClientAppException(str(ex)) from ex
flwr.client.client_app.ClientAppException: 
Exception ClientAppException occurred. Message: [Errno 2] No such file or directory: 'rl_poisoning_agent.zip'

2025-04-30 11:23:18 - ERROR - [36mray::ClientAppActor.run()[39m (pid=13392, ip=127.0.0.1, actor_id=41bbf42d74299670ad7431d601000000, repr=<flwr.simulation.ray_transport.ray_actor.ClientAppActor object at 0x000002D18018C970>)
  File "C:\RL Adaptive Model Poisoning Attacks in FL\.venv\lib\site-packages\flwr\client\client_app.py", line 144, in __call__
    return self._call(message, context)
  File "C:\RL Adaptive Model Poisoning Attacks in FL\.venv\lib\site-packages\flwr\client\client_app.py", line 128, in ffn
    out_message = handle_legacy_message_from_msgtype(
  File "C:\RL Adaptive Model Poisoning Attacks in FL\.venv\lib\site-packages\flwr\client\message_handler\message_handler.py", line 96, in handle_legacy_message_from_msgtype
    client = client_fn(context)
  File "C:\RL Adaptive Model Poisoning Attacks in FL\.venv\lib\site-packages\flwr\client\client_app.py", line 72, in adaptor_fn
    return client_fn(str(cid))  # type: ignore
  File "C:\RL Adaptive Model Poisoning Attacks in FL\federated_learning\server.py", line 154, in client_fn
    return poisoned_client_fn(
  File "C:\RL Adaptive Model Poisoning Attacks in FL\federated_learning\poisoned_client.py", line 150, in poisoned_client_fn
    return Poisoned_AdaptiveClient(
  File "C:\RL Adaptive Model Poisoning Attacks in FL\federated_learning\poisoned_client.py", line 37, in __init__
    self.poisoner = RLAdaptiveModelPoisoning()
  File "C:\RL Adaptive Model Poisoning Attacks in FL\federated_learning\attacks\deep_rl_adaptive_model_poisoning.py", line 7, in __init__
    self.model = DQN.load(agent_path)
  File "C:\RL Adaptive Model Poisoning Attacks in FL\.venv\lib\site-packages\stable_baselines3\common\base_class.py", line 681, in load
    data, params, pytorch_variables = load_from_zip_file(
  File "C:\RL Adaptive Model Poisoning Attacks in FL\.venv\lib\site-packages\stable_baselines3\common\save_util.py", line 403, in load_from_zip_file
    file = open_path(load_path, "r", verbose=verbose, suffix="zip")
  File "C:\Program Files\WindowsApps\PythonSoftwareFoundation.Python.3.9_3.9.3568.0_x64__qbz5n2kfra8p0\lib\functools.py", line 888, in wrapper
    return dispatch(args[0].__class__)(*args, **kw)
  File "C:\RL Adaptive Model Poisoning Attacks in FL\.venv\lib\site-packages\stable_baselines3\common\save_util.py", line 240, in open_path_str
    return open_path_pathlib(pathlib.Path(path), mode, verbose, suffix)
  File "C:\RL Adaptive Model Poisoning Attacks in FL\.venv\lib\site-packages\stable_baselines3\common\save_util.py", line 291, in open_path_pathlib
    return open_path_pathlib(path, mode, verbose, suffix)
  File "C:\RL Adaptive Model Poisoning Attacks in FL\.venv\lib\site-packages\stable_baselines3\common\save_util.py", line 272, in open_path_pathlib
    raise error
  File "C:\RL Adaptive Model Poisoning Attacks in FL\.venv\lib\site-packages\stable_baselines3\common\save_util.py", line 264, in open_path_pathlib
    return open_path(path.open("rb"), mode, verbose, suffix)
  File "C:\Program Files\WindowsApps\PythonSoftwareFoundation.Python.3.9_3.9.3568.0_x64__qbz5n2kfra8p0\lib\pathlib.py", line 1252, in open
    return io.open(self, mode, buffering, encoding, errors, newline,
  File "C:\Program Files\WindowsApps\PythonSoftwareFoundation.Python.3.9_3.9.3568.0_x64__qbz5n2kfra8p0\lib\pathlib.py", line 1120, in _opener
    return self._accessor.open(self, flags, mode)
FileNotFoundError: [Errno 2] No such file or directory: 'rl_poisoning_agent.zip'

The above exception was the direct cause of the following exception:

[36mray::ClientAppActor.run()[39m (pid=13392, ip=127.0.0.1, actor_id=41bbf42d74299670ad7431d601000000, repr=<flwr.simulation.ray_transport.ray_actor.ClientAppActor object at 0x000002D18018C970>)
  File "python\ray\_raylet.pyx", line 1890, in ray._raylet.execute_task
  File "python\ray\_raylet.pyx", line 1991, in ray._raylet.execute_task
  File "python\ray\_raylet.pyx", line 1896, in ray._raylet.execute_task
  File "python\ray\_raylet.pyx", line 1837, in ray._raylet.execute_task.function_executor
  File "C:\RL Adaptive Model Poisoning Attacks in FL\.venv\lib\site-packages\ray\_private\function_manager.py", line 691, in actor_method_executor
    return method(__ray_actor, *args, **kwargs)
  File "C:\RL Adaptive Model Poisoning Attacks in FL\.venv\lib\site-packages\ray\util\tracing\tracing_helper.py", line 467, in _resume_span
    return method(self, *_args, **_kwargs)
  File "C:\RL Adaptive Model Poisoning Attacks in FL\.venv\lib\site-packages\flwr\simulation\ray_transport\ray_actor.py", line 64, in run
    raise ClientAppException(str(ex)) from ex
flwr.client.client_app.ClientAppException: 
Exception ClientAppException occurred. Message: [Errno 2] No such file or directory: 'rl_poisoning_agent.zip'
2025-04-30 11:23:18 - ERROR - Traceback (most recent call last):
  File "C:\RL Adaptive Model Poisoning Attacks in FL\.venv\lib\site-packages\flwr\simulation\ray_transport\ray_client_proxy.py", line 95, in _submit_job
    out_mssg, updated_context = self.actor_pool.get_client_result(
  File "C:\RL Adaptive Model Poisoning Attacks in FL\.venv\lib\site-packages\flwr\simulation\ray_transport\ray_actor.py", line 401, in get_client_result
    return self._fetch_future_result(cid)
  File "C:\RL Adaptive Model Poisoning Attacks in FL\.venv\lib\site-packages\flwr\simulation\ray_transport\ray_actor.py", line 282, in _fetch_future_result
    res_cid, out_mssg, updated_context = ray.get(
  File "C:\RL Adaptive Model Poisoning Attacks in FL\.venv\lib\site-packages\ray\_private\auto_init_hook.py", line 21, in auto_init_wrapper
    return fn(*args, **kwargs)
  File "C:\RL Adaptive Model Poisoning Attacks in FL\.venv\lib\site-packages\ray\_private\client_mode_hook.py", line 103, in wrapper
    return func(*args, **kwargs)
  File "C:\RL Adaptive Model Poisoning Attacks in FL\.venv\lib\site-packages\ray\_private\worker.py", line 2639, in get
    values, debugger_breakpoint = worker.get_objects(object_refs, timeout=timeout)
  File "C:\RL Adaptive Model Poisoning Attacks in FL\.venv\lib\site-packages\ray\_private\worker.py", line 864, in get_objects
    raise value.as_instanceof_cause()
ray.exceptions.RayTaskError(ClientAppException): [36mray::ClientAppActor.run()[39m (pid=13164, ip=127.0.0.1, actor_id=4677a1fadab7cc85ad94db9501000000, repr=<flwr.simulation.ray_transport.ray_actor.ClientAppActor object at 0x000002B980CCCDC0>)
  File "C:\RL Adaptive Model Poisoning Attacks in FL\.venv\lib\site-packages\flwr\client\client_app.py", line 144, in __call__
    return self._call(message, context)
  File "C:\RL Adaptive Model Poisoning Attacks in FL\.venv\lib\site-packages\flwr\client\client_app.py", line 128, in ffn
    out_message = handle_legacy_message_from_msgtype(
  File "C:\RL Adaptive Model Poisoning Attacks in FL\.venv\lib\site-packages\flwr\client\message_handler\message_handler.py", line 96, in handle_legacy_message_from_msgtype
    client = client_fn(context)
  File "C:\RL Adaptive Model Poisoning Attacks in FL\.venv\lib\site-packages\flwr\client\client_app.py", line 72, in adaptor_fn
    return client_fn(str(cid))  # type: ignore
  File "C:\RL Adaptive Model Poisoning Attacks in FL\federated_learning\server.py", line 154, in client_fn
    return poisoned_client_fn(
  File "C:\RL Adaptive Model Poisoning Attacks in FL\federated_learning\poisoned_client.py", line 150, in poisoned_client_fn
    return Poisoned_AdaptiveClient(
  File "C:\RL Adaptive Model Poisoning Attacks in FL\federated_learning\poisoned_client.py", line 37, in __init__
    self.poisoner = RLAdaptiveModelPoisoning()
  File "C:\RL Adaptive Model Poisoning Attacks in FL\federated_learning\attacks\deep_rl_adaptive_model_poisoning.py", line 7, in __init__
    self.model = DQN.load(agent_path)
  File "C:\RL Adaptive Model Poisoning Attacks in FL\.venv\lib\site-packages\stable_baselines3\common\base_class.py", line 681, in load
    data, params, pytorch_variables = load_from_zip_file(
  File "C:\RL Adaptive Model Poisoning Attacks in FL\.venv\lib\site-packages\stable_baselines3\common\save_util.py", line 403, in load_from_zip_file
    file = open_path(load_path, "r", verbose=verbose, suffix="zip")
  File "C:\Program Files\WindowsApps\PythonSoftwareFoundation.Python.3.9_3.9.3568.0_x64__qbz5n2kfra8p0\lib\functools.py", line 888, in wrapper
    return dispatch(args[0].__class__)(*args, **kw)
  File "C:\RL Adaptive Model Poisoning Attacks in FL\.venv\lib\site-packages\stable_baselines3\common\save_util.py", line 240, in open_path_str
    return open_path_pathlib(pathlib.Path(path), mode, verbose, suffix)
  File "C:\RL Adaptive Model Poisoning Attacks in FL\.venv\lib\site-packages\stable_baselines3\common\save_util.py", line 291, in open_path_pathlib
    return open_path_pathlib(path, mode, verbose, suffix)
  File "C:\RL Adaptive Model Poisoning Attacks in FL\.venv\lib\site-packages\stable_baselines3\common\save_util.py", line 272, in open_path_pathlib
    raise error
  File "C:\RL Adaptive Model Poisoning Attacks in FL\.venv\lib\site-packages\stable_baselines3\common\save_util.py", line 264, in open_path_pathlib
    return open_path(path.open("rb"), mode, verbose, suffix)
  File "C:\Program Files\WindowsApps\PythonSoftwareFoundation.Python.3.9_3.9.3568.0_x64__qbz5n2kfra8p0\lib\pathlib.py", line 1252, in open
    return io.open(self, mode, buffering, encoding, errors, newline,
  File "C:\Program Files\WindowsApps\PythonSoftwareFoundation.Python.3.9_3.9.3568.0_x64__qbz5n2kfra8p0\lib\pathlib.py", line 1120, in _opener
    return self._accessor.open(self, flags, mode)
FileNotFoundError: [Errno 2] No such file or directory: 'rl_poisoning_agent.zip'

The above exception was the direct cause of the following exception:

[36mray::ClientAppActor.run()[39m (pid=13164, ip=127.0.0.1, actor_id=4677a1fadab7cc85ad94db9501000000, repr=<flwr.simulation.ray_transport.ray_actor.ClientAppActor object at 0x000002B980CCCDC0>)
  File "python\ray\_raylet.pyx", line 1890, in ray._raylet.execute_task
  File "python\ray\_raylet.pyx", line 1991, in ray._raylet.execute_task
  File "python\ray\_raylet.pyx", line 1896, in ray._raylet.execute_task
  File "python\ray\_raylet.pyx", line 1837, in ray._raylet.execute_task.function_executor
  File "C:\RL Adaptive Model Poisoning Attacks in FL\.venv\lib\site-packages\ray\_private\function_manager.py", line 691, in actor_method_executor
    return method(__ray_actor, *args, **kwargs)
  File "C:\RL Adaptive Model Poisoning Attacks in FL\.venv\lib\site-packages\ray\util\tracing\tracing_helper.py", line 467, in _resume_span
    return method(self, *_args, **_kwargs)
  File "C:\RL Adaptive Model Poisoning Attacks in FL\.venv\lib\site-packages\flwr\simulation\ray_transport\ray_actor.py", line 64, in run
    raise ClientAppException(str(ex)) from ex
flwr.client.client_app.ClientAppException: 
Exception ClientAppException occurred. Message: [Errno 2] No such file or directory: 'rl_poisoning_agent.zip'

2025-04-30 11:23:18 - ERROR - [36mray::ClientAppActor.run()[39m (pid=13164, ip=127.0.0.1, actor_id=4677a1fadab7cc85ad94db9501000000, repr=<flwr.simulation.ray_transport.ray_actor.ClientAppActor object at 0x000002B980CCCDC0>)
  File "C:\RL Adaptive Model Poisoning Attacks in FL\.venv\lib\site-packages\flwr\client\client_app.py", line 144, in __call__
    return self._call(message, context)
  File "C:\RL Adaptive Model Poisoning Attacks in FL\.venv\lib\site-packages\flwr\client\client_app.py", line 128, in ffn
    out_message = handle_legacy_message_from_msgtype(
  File "C:\RL Adaptive Model Poisoning Attacks in FL\.venv\lib\site-packages\flwr\client\message_handler\message_handler.py", line 96, in handle_legacy_message_from_msgtype
    client = client_fn(context)
  File "C:\RL Adaptive Model Poisoning Attacks in FL\.venv\lib\site-packages\flwr\client\client_app.py", line 72, in adaptor_fn
    return client_fn(str(cid))  # type: ignore
  File "C:\RL Adaptive Model Poisoning Attacks in FL\federated_learning\server.py", line 154, in client_fn
    return poisoned_client_fn(
  File "C:\RL Adaptive Model Poisoning Attacks in FL\federated_learning\poisoned_client.py", line 150, in poisoned_client_fn
    return Poisoned_AdaptiveClient(
  File "C:\RL Adaptive Model Poisoning Attacks in FL\federated_learning\poisoned_client.py", line 37, in __init__
    self.poisoner = RLAdaptiveModelPoisoning()
  File "C:\RL Adaptive Model Poisoning Attacks in FL\federated_learning\attacks\deep_rl_adaptive_model_poisoning.py", line 7, in __init__
    self.model = DQN.load(agent_path)
  File "C:\RL Adaptive Model Poisoning Attacks in FL\.venv\lib\site-packages\stable_baselines3\common\base_class.py", line 681, in load
    data, params, pytorch_variables = load_from_zip_file(
  File "C:\RL Adaptive Model Poisoning Attacks in FL\.venv\lib\site-packages\stable_baselines3\common\save_util.py", line 403, in load_from_zip_file
    file = open_path(load_path, "r", verbose=verbose, suffix="zip")
  File "C:\Program Files\WindowsApps\PythonSoftwareFoundation.Python.3.9_3.9.3568.0_x64__qbz5n2kfra8p0\lib\functools.py", line 888, in wrapper
    return dispatch(args[0].__class__)(*args, **kw)
  File "C:\RL Adaptive Model Poisoning Attacks in FL\.venv\lib\site-packages\stable_baselines3\common\save_util.py", line 240, in open_path_str
    return open_path_pathlib(pathlib.Path(path), mode, verbose, suffix)
  File "C:\RL Adaptive Model Poisoning Attacks in FL\.venv\lib\site-packages\stable_baselines3\common\save_util.py", line 291, in open_path_pathlib
    return open_path_pathlib(path, mode, verbose, suffix)
  File "C:\RL Adaptive Model Poisoning Attacks in FL\.venv\lib\site-packages\stable_baselines3\common\save_util.py", line 272, in open_path_pathlib
    raise error
  File "C:\RL Adaptive Model Poisoning Attacks in FL\.venv\lib\site-packages\stable_baselines3\common\save_util.py", line 264, in open_path_pathlib
    return open_path(path.open("rb"), mode, verbose, suffix)
  File "C:\Program Files\WindowsApps\PythonSoftwareFoundation.Python.3.9_3.9.3568.0_x64__qbz5n2kfra8p0\lib\pathlib.py", line 1252, in open
    return io.open(self, mode, buffering, encoding, errors, newline,
  File "C:\Program Files\WindowsApps\PythonSoftwareFoundation.Python.3.9_3.9.3568.0_x64__qbz5n2kfra8p0\lib\pathlib.py", line 1120, in _opener
    return self._accessor.open(self, flags, mode)
FileNotFoundError: [Errno 2] No such file or directory: 'rl_poisoning_agent.zip'

The above exception was the direct cause of the following exception:

[36mray::ClientAppActor.run()[39m (pid=13164, ip=127.0.0.1, actor_id=4677a1fadab7cc85ad94db9501000000, repr=<flwr.simulation.ray_transport.ray_actor.ClientAppActor object at 0x000002B980CCCDC0>)
  File "python\ray\_raylet.pyx", line 1890, in ray._raylet.execute_task
  File "python\ray\_raylet.pyx", line 1991, in ray._raylet.execute_task
  File "python\ray\_raylet.pyx", line 1896, in ray._raylet.execute_task
  File "python\ray\_raylet.pyx", line 1837, in ray._raylet.execute_task.function_executor
  File "C:\RL Adaptive Model Poisoning Attacks in FL\.venv\lib\site-packages\ray\_private\function_manager.py", line 691, in actor_method_executor
    return method(__ray_actor, *args, **kwargs)
  File "C:\RL Adaptive Model Poisoning Attacks in FL\.venv\lib\site-packages\ray\util\tracing\tracing_helper.py", line 467, in _resume_span
    return method(self, *_args, **_kwargs)
  File "C:\RL Adaptive Model Poisoning Attacks in FL\.venv\lib\site-packages\flwr\simulation\ray_transport\ray_actor.py", line 64, in run
    raise ClientAppException(str(ex)) from ex
flwr.client.client_app.ClientAppException: 
Exception ClientAppException occurred. Message: [Errno 2] No such file or directory: 'rl_poisoning_agent.zip'
2025-04-30 11:23:18 - ERROR - Traceback (most recent call last):
  File "C:\RL Adaptive Model Poisoning Attacks in FL\.venv\lib\site-packages\flwr\simulation\ray_transport\ray_client_proxy.py", line 95, in _submit_job
    out_mssg, updated_context = self.actor_pool.get_client_result(
  File "C:\RL Adaptive Model Poisoning Attacks in FL\.venv\lib\site-packages\flwr\simulation\ray_transport\ray_actor.py", line 401, in get_client_result
    return self._fetch_future_result(cid)
  File "C:\RL Adaptive Model Poisoning Attacks in FL\.venv\lib\site-packages\flwr\simulation\ray_transport\ray_actor.py", line 282, in _fetch_future_result
    res_cid, out_mssg, updated_context = ray.get(
  File "C:\RL Adaptive Model Poisoning Attacks in FL\.venv\lib\site-packages\ray\_private\auto_init_hook.py", line 21, in auto_init_wrapper
    return fn(*args, **kwargs)
  File "C:\RL Adaptive Model Poisoning Attacks in FL\.venv\lib\site-packages\ray\_private\client_mode_hook.py", line 103, in wrapper
    return func(*args, **kwargs)
  File "C:\RL Adaptive Model Poisoning Attacks in FL\.venv\lib\site-packages\ray\_private\worker.py", line 2639, in get
    values, debugger_breakpoint = worker.get_objects(object_refs, timeout=timeout)
  File "C:\RL Adaptive Model Poisoning Attacks in FL\.venv\lib\site-packages\ray\_private\worker.py", line 864, in get_objects
    raise value.as_instanceof_cause()
ray.exceptions.RayTaskError(ClientAppException): [36mray::ClientAppActor.run()[39m (pid=25572, ip=127.0.0.1, actor_id=dfaf794046da249e9a81aefa01000000, repr=<flwr.simulation.ray_transport.ray_actor.ClientAppActor object at 0x0000020C84B6B940>)
  File "C:\RL Adaptive Model Poisoning Attacks in FL\.venv\lib\site-packages\flwr\client\client_app.py", line 144, in __call__
    return self._call(message, context)
  File "C:\RL Adaptive Model Poisoning Attacks in FL\.venv\lib\site-packages\flwr\client\client_app.py", line 128, in ffn
    out_message = handle_legacy_message_from_msgtype(
  File "C:\RL Adaptive Model Poisoning Attacks in FL\.venv\lib\site-packages\flwr\client\message_handler\message_handler.py", line 96, in handle_legacy_message_from_msgtype
    client = client_fn(context)
  File "C:\RL Adaptive Model Poisoning Attacks in FL\.venv\lib\site-packages\flwr\client\client_app.py", line 72, in adaptor_fn
    return client_fn(str(cid))  # type: ignore
  File "C:\RL Adaptive Model Poisoning Attacks in FL\federated_learning\server.py", line 154, in client_fn
    return poisoned_client_fn(
  File "C:\RL Adaptive Model Poisoning Attacks in FL\federated_learning\poisoned_client.py", line 150, in poisoned_client_fn
    return Poisoned_AdaptiveClient(
  File "C:\RL Adaptive Model Poisoning Attacks in FL\federated_learning\poisoned_client.py", line 37, in __init__
    self.poisoner = RLAdaptiveModelPoisoning()
  File "C:\RL Adaptive Model Poisoning Attacks in FL\federated_learning\attacks\deep_rl_adaptive_model_poisoning.py", line 7, in __init__
    self.model = DQN.load(agent_path)
  File "C:\RL Adaptive Model Poisoning Attacks in FL\.venv\lib\site-packages\stable_baselines3\common\base_class.py", line 681, in load
    data, params, pytorch_variables = load_from_zip_file(
  File "C:\RL Adaptive Model Poisoning Attacks in FL\.venv\lib\site-packages\stable_baselines3\common\save_util.py", line 403, in load_from_zip_file
    file = open_path(load_path, "r", verbose=verbose, suffix="zip")
  File "C:\Program Files\WindowsApps\PythonSoftwareFoundation.Python.3.9_3.9.3568.0_x64__qbz5n2kfra8p0\lib\functools.py", line 888, in wrapper
    return dispatch(args[0].__class__)(*args, **kw)
  File "C:\RL Adaptive Model Poisoning Attacks in FL\.venv\lib\site-packages\stable_baselines3\common\save_util.py", line 240, in open_path_str
    return open_path_pathlib(pathlib.Path(path), mode, verbose, suffix)
  File "C:\RL Adaptive Model Poisoning Attacks in FL\.venv\lib\site-packages\stable_baselines3\common\save_util.py", line 291, in open_path_pathlib
    return open_path_pathlib(path, mode, verbose, suffix)
  File "C:\RL Adaptive Model Poisoning Attacks in FL\.venv\lib\site-packages\stable_baselines3\common\save_util.py", line 272, in open_path_pathlib
    raise error
  File "C:\RL Adaptive Model Poisoning Attacks in FL\.venv\lib\site-packages\stable_baselines3\common\save_util.py", line 264, in open_path_pathlib
    return open_path(path.open("rb"), mode, verbose, suffix)
  File "C:\Program Files\WindowsApps\PythonSoftwareFoundation.Python.3.9_3.9.3568.0_x64__qbz5n2kfra8p0\lib\pathlib.py", line 1252, in open
    return io.open(self, mode, buffering, encoding, errors, newline,
  File "C:\Program Files\WindowsApps\PythonSoftwareFoundation.Python.3.9_3.9.3568.0_x64__qbz5n2kfra8p0\lib\pathlib.py", line 1120, in _opener
    return self._accessor.open(self, flags, mode)
FileNotFoundError: [Errno 2] No such file or directory: 'rl_poisoning_agent.zip'

The above exception was the direct cause of the following exception:

[36mray::ClientAppActor.run()[39m (pid=25572, ip=127.0.0.1, actor_id=dfaf794046da249e9a81aefa01000000, repr=<flwr.simulation.ray_transport.ray_actor.ClientAppActor object at 0x0000020C84B6B940>)
  File "python\ray\_raylet.pyx", line 1890, in ray._raylet.execute_task
  File "python\ray\_raylet.pyx", line 1991, in ray._raylet.execute_task
  File "python\ray\_raylet.pyx", line 1896, in ray._raylet.execute_task
  File "python\ray\_raylet.pyx", line 1837, in ray._raylet.execute_task.function_executor
  File "C:\RL Adaptive Model Poisoning Attacks in FL\.venv\lib\site-packages\ray\_private\function_manager.py", line 691, in actor_method_executor
    return method(__ray_actor, *args, **kwargs)
  File "C:\RL Adaptive Model Poisoning Attacks in FL\.venv\lib\site-packages\ray\util\tracing\tracing_helper.py", line 467, in _resume_span
    return method(self, *_args, **_kwargs)
  File "C:\RL Adaptive Model Poisoning Attacks in FL\.venv\lib\site-packages\flwr\simulation\ray_transport\ray_actor.py", line 64, in run
    raise ClientAppException(str(ex)) from ex
flwr.client.client_app.ClientAppException: 
Exception ClientAppException occurred. Message: [Errno 2] No such file or directory: 'rl_poisoning_agent.zip'

2025-04-30 11:23:18 - ERROR - [36mray::ClientAppActor.run()[39m (pid=25572, ip=127.0.0.1, actor_id=dfaf794046da249e9a81aefa01000000, repr=<flwr.simulation.ray_transport.ray_actor.ClientAppActor object at 0x0000020C84B6B940>)
  File "C:\RL Adaptive Model Poisoning Attacks in FL\.venv\lib\site-packages\flwr\client\client_app.py", line 144, in __call__
    return self._call(message, context)
  File "C:\RL Adaptive Model Poisoning Attacks in FL\.venv\lib\site-packages\flwr\client\client_app.py", line 128, in ffn
    out_message = handle_legacy_message_from_msgtype(
  File "C:\RL Adaptive Model Poisoning Attacks in FL\.venv\lib\site-packages\flwr\client\message_handler\message_handler.py", line 96, in handle_legacy_message_from_msgtype
    client = client_fn(context)
  File "C:\RL Adaptive Model Poisoning Attacks in FL\.venv\lib\site-packages\flwr\client\client_app.py", line 72, in adaptor_fn
    return client_fn(str(cid))  # type: ignore
  File "C:\RL Adaptive Model Poisoning Attacks in FL\federated_learning\server.py", line 154, in client_fn
    return poisoned_client_fn(
  File "C:\RL Adaptive Model Poisoning Attacks in FL\federated_learning\poisoned_client.py", line 150, in poisoned_client_fn
    return Poisoned_AdaptiveClient(
  File "C:\RL Adaptive Model Poisoning Attacks in FL\federated_learning\poisoned_client.py", line 37, in __init__
    self.poisoner = RLAdaptiveModelPoisoning()
  File "C:\RL Adaptive Model Poisoning Attacks in FL\federated_learning\attacks\deep_rl_adaptive_model_poisoning.py", line 7, in __init__
    self.model = DQN.load(agent_path)
  File "C:\RL Adaptive Model Poisoning Attacks in FL\.venv\lib\site-packages\stable_baselines3\common\base_class.py", line 681, in load
    data, params, pytorch_variables = load_from_zip_file(
  File "C:\RL Adaptive Model Poisoning Attacks in FL\.venv\lib\site-packages\stable_baselines3\common\save_util.py", line 403, in load_from_zip_file
    file = open_path(load_path, "r", verbose=verbose, suffix="zip")
  File "C:\Program Files\WindowsApps\PythonSoftwareFoundation.Python.3.9_3.9.3568.0_x64__qbz5n2kfra8p0\lib\functools.py", line 888, in wrapper
    return dispatch(args[0].__class__)(*args, **kw)
  File "C:\RL Adaptive Model Poisoning Attacks in FL\.venv\lib\site-packages\stable_baselines3\common\save_util.py", line 240, in open_path_str
    return open_path_pathlib(pathlib.Path(path), mode, verbose, suffix)
  File "C:\RL Adaptive Model Poisoning Attacks in FL\.venv\lib\site-packages\stable_baselines3\common\save_util.py", line 291, in open_path_pathlib
    return open_path_pathlib(path, mode, verbose, suffix)
  File "C:\RL Adaptive Model Poisoning Attacks in FL\.venv\lib\site-packages\stable_baselines3\common\save_util.py", line 272, in open_path_pathlib
    raise error
  File "C:\RL Adaptive Model Poisoning Attacks in FL\.venv\lib\site-packages\stable_baselines3\common\save_util.py", line 264, in open_path_pathlib
    return open_path(path.open("rb"), mode, verbose, suffix)
  File "C:\Program Files\WindowsApps\PythonSoftwareFoundation.Python.3.9_3.9.3568.0_x64__qbz5n2kfra8p0\lib\pathlib.py", line 1252, in open
    return io.open(self, mode, buffering, encoding, errors, newline,
  File "C:\Program Files\WindowsApps\PythonSoftwareFoundation.Python.3.9_3.9.3568.0_x64__qbz5n2kfra8p0\lib\pathlib.py", line 1120, in _opener
    return self._accessor.open(self, flags, mode)
FileNotFoundError: [Errno 2] No such file or directory: 'rl_poisoning_agent.zip'

The above exception was the direct cause of the following exception:

[36mray::ClientAppActor.run()[39m (pid=25572, ip=127.0.0.1, actor_id=dfaf794046da249e9a81aefa01000000, repr=<flwr.simulation.ray_transport.ray_actor.ClientAppActor object at 0x0000020C84B6B940>)
  File "python\ray\_raylet.pyx", line 1890, in ray._raylet.execute_task
  File "python\ray\_raylet.pyx", line 1991, in ray._raylet.execute_task
  File "python\ray\_raylet.pyx", line 1896, in ray._raylet.execute_task
  File "python\ray\_raylet.pyx", line 1837, in ray._raylet.execute_task.function_executor
  File "C:\RL Adaptive Model Poisoning Attacks in FL\.venv\lib\site-packages\ray\_private\function_manager.py", line 691, in actor_method_executor
    return method(__ray_actor, *args, **kwargs)
  File "C:\RL Adaptive Model Poisoning Attacks in FL\.venv\lib\site-packages\ray\util\tracing\tracing_helper.py", line 467, in _resume_span
    return method(self, *_args, **_kwargs)
  File "C:\RL Adaptive Model Poisoning Attacks in FL\.venv\lib\site-packages\flwr\simulation\ray_transport\ray_actor.py", line 64, in run
    raise ClientAppException(str(ex)) from ex
flwr.client.client_app.ClientAppException: 
Exception ClientAppException occurred. Message: [Errno 2] No such file or directory: 'rl_poisoning_agent.zip'
2025-04-30 11:23:18 - ERROR - Traceback (most recent call last):
  File "C:\RL Adaptive Model Poisoning Attacks in FL\.venv\lib\site-packages\flwr\simulation\ray_transport\ray_client_proxy.py", line 95, in _submit_job
    out_mssg, updated_context = self.actor_pool.get_client_result(
  File "C:\RL Adaptive Model Poisoning Attacks in FL\.venv\lib\site-packages\flwr\simulation\ray_transport\ray_actor.py", line 401, in get_client_result
    return self._fetch_future_result(cid)
  File "C:\RL Adaptive Model Poisoning Attacks in FL\.venv\lib\site-packages\flwr\simulation\ray_transport\ray_actor.py", line 282, in _fetch_future_result
    res_cid, out_mssg, updated_context = ray.get(
  File "C:\RL Adaptive Model Poisoning Attacks in FL\.venv\lib\site-packages\ray\_private\auto_init_hook.py", line 21, in auto_init_wrapper
    return fn(*args, **kwargs)
  File "C:\RL Adaptive Model Poisoning Attacks in FL\.venv\lib\site-packages\ray\_private\client_mode_hook.py", line 103, in wrapper
    return func(*args, **kwargs)
  File "C:\RL Adaptive Model Poisoning Attacks in FL\.venv\lib\site-packages\ray\_private\worker.py", line 2639, in get
    values, debugger_breakpoint = worker.get_objects(object_refs, timeout=timeout)
  File "C:\RL Adaptive Model Poisoning Attacks in FL\.venv\lib\site-packages\ray\_private\worker.py", line 864, in get_objects
    raise value.as_instanceof_cause()
ray.exceptions.RayTaskError(ClientAppException): [36mray::ClientAppActor.run()[39m (pid=38964, ip=127.0.0.1, actor_id=b010d368fd758746a05040e901000000, repr=<flwr.simulation.ray_transport.ray_actor.ClientAppActor object at 0x000002E280ABC9A0>)
  File "C:\RL Adaptive Model Poisoning Attacks in FL\.venv\lib\site-packages\flwr\client\client_app.py", line 144, in __call__
    return self._call(message, context)
  File "C:\RL Adaptive Model Poisoning Attacks in FL\.venv\lib\site-packages\flwr\client\client_app.py", line 128, in ffn
    out_message = handle_legacy_message_from_msgtype(
  File "C:\RL Adaptive Model Poisoning Attacks in FL\.venv\lib\site-packages\flwr\client\message_handler\message_handler.py", line 96, in handle_legacy_message_from_msgtype
    client = client_fn(context)
  File "C:\RL Adaptive Model Poisoning Attacks in FL\.venv\lib\site-packages\flwr\client\client_app.py", line 72, in adaptor_fn
    return client_fn(str(cid))  # type: ignore
  File "C:\RL Adaptive Model Poisoning Attacks in FL\federated_learning\server.py", line 154, in client_fn
    return poisoned_client_fn(
  File "C:\RL Adaptive Model Poisoning Attacks in FL\federated_learning\poisoned_client.py", line 150, in poisoned_client_fn
    return Poisoned_AdaptiveClient(
  File "C:\RL Adaptive Model Poisoning Attacks in FL\federated_learning\poisoned_client.py", line 37, in __init__
    self.poisoner = RLAdaptiveModelPoisoning()
  File "C:\RL Adaptive Model Poisoning Attacks in FL\federated_learning\attacks\deep_rl_adaptive_model_poisoning.py", line 7, in __init__
    self.model = DQN.load(agent_path)
  File "C:\RL Adaptive Model Poisoning Attacks in FL\.venv\lib\site-packages\stable_baselines3\common\base_class.py", line 681, in load
    data, params, pytorch_variables = load_from_zip_file(
  File "C:\RL Adaptive Model Poisoning Attacks in FL\.venv\lib\site-packages\stable_baselines3\common\save_util.py", line 403, in load_from_zip_file
    file = open_path(load_path, "r", verbose=verbose, suffix="zip")
  File "C:\Program Files\WindowsApps\PythonSoftwareFoundation.Python.3.9_3.9.3568.0_x64__qbz5n2kfra8p0\lib\functools.py", line 888, in wrapper
    return dispatch(args[0].__class__)(*args, **kw)
  File "C:\RL Adaptive Model Poisoning Attacks in FL\.venv\lib\site-packages\stable_baselines3\common\save_util.py", line 240, in open_path_str
    return open_path_pathlib(pathlib.Path(path), mode, verbose, suffix)
  File "C:\RL Adaptive Model Poisoning Attacks in FL\.venv\lib\site-packages\stable_baselines3\common\save_util.py", line 291, in open_path_pathlib
    return open_path_pathlib(path, mode, verbose, suffix)
  File "C:\RL Adaptive Model Poisoning Attacks in FL\.venv\lib\site-packages\stable_baselines3\common\save_util.py", line 272, in open_path_pathlib
    raise error
  File "C:\RL Adaptive Model Poisoning Attacks in FL\.venv\lib\site-packages\stable_baselines3\common\save_util.py", line 264, in open_path_pathlib
    return open_path(path.open("rb"), mode, verbose, suffix)
  File "C:\Program Files\WindowsApps\PythonSoftwareFoundation.Python.3.9_3.9.3568.0_x64__qbz5n2kfra8p0\lib\pathlib.py", line 1252, in open
    return io.open(self, mode, buffering, encoding, errors, newline,
  File "C:\Program Files\WindowsApps\PythonSoftwareFoundation.Python.3.9_3.9.3568.0_x64__qbz5n2kfra8p0\lib\pathlib.py", line 1120, in _opener
    return self._accessor.open(self, flags, mode)
FileNotFoundError: [Errno 2] No such file or directory: 'rl_poisoning_agent.zip'

The above exception was the direct cause of the following exception:

[36mray::ClientAppActor.run()[39m (pid=38964, ip=127.0.0.1, actor_id=b010d368fd758746a05040e901000000, repr=<flwr.simulation.ray_transport.ray_actor.ClientAppActor object at 0x000002E280ABC9A0>)
  File "python\ray\_raylet.pyx", line 1890, in ray._raylet.execute_task
  File "python\ray\_raylet.pyx", line 1991, in ray._raylet.execute_task
  File "python\ray\_raylet.pyx", line 1896, in ray._raylet.execute_task
  File "python\ray\_raylet.pyx", line 1837, in ray._raylet.execute_task.function_executor
  File "C:\RL Adaptive Model Poisoning Attacks in FL\.venv\lib\site-packages\ray\_private\function_manager.py", line 691, in actor_method_executor
    return method(__ray_actor, *args, **kwargs)
  File "C:\RL Adaptive Model Poisoning Attacks in FL\.venv\lib\site-packages\ray\util\tracing\tracing_helper.py", line 467, in _resume_span
    return method(self, *_args, **_kwargs)
  File "C:\RL Adaptive Model Poisoning Attacks in FL\.venv\lib\site-packages\flwr\simulation\ray_transport\ray_actor.py", line 64, in run
    raise ClientAppException(str(ex)) from ex
flwr.client.client_app.ClientAppException: 
Exception ClientAppException occurred. Message: [Errno 2] No such file or directory: 'rl_poisoning_agent.zip'

2025-04-30 11:23:18 - ERROR - [36mray::ClientAppActor.run()[39m (pid=38964, ip=127.0.0.1, actor_id=b010d368fd758746a05040e901000000, repr=<flwr.simulation.ray_transport.ray_actor.ClientAppActor object at 0x000002E280ABC9A0>)
  File "C:\RL Adaptive Model Poisoning Attacks in FL\.venv\lib\site-packages\flwr\client\client_app.py", line 144, in __call__
    return self._call(message, context)
  File "C:\RL Adaptive Model Poisoning Attacks in FL\.venv\lib\site-packages\flwr\client\client_app.py", line 128, in ffn
    out_message = handle_legacy_message_from_msgtype(
  File "C:\RL Adaptive Model Poisoning Attacks in FL\.venv\lib\site-packages\flwr\client\message_handler\message_handler.py", line 96, in handle_legacy_message_from_msgtype
    client = client_fn(context)
  File "C:\RL Adaptive Model Poisoning Attacks in FL\.venv\lib\site-packages\flwr\client\client_app.py", line 72, in adaptor_fn
    return client_fn(str(cid))  # type: ignore
  File "C:\RL Adaptive Model Poisoning Attacks in FL\federated_learning\server.py", line 154, in client_fn
    return poisoned_client_fn(
  File "C:\RL Adaptive Model Poisoning Attacks in FL\federated_learning\poisoned_client.py", line 150, in poisoned_client_fn
    return Poisoned_AdaptiveClient(
  File "C:\RL Adaptive Model Poisoning Attacks in FL\federated_learning\poisoned_client.py", line 37, in __init__
    self.poisoner = RLAdaptiveModelPoisoning()
  File "C:\RL Adaptive Model Poisoning Attacks in FL\federated_learning\attacks\deep_rl_adaptive_model_poisoning.py", line 7, in __init__
    self.model = DQN.load(agent_path)
  File "C:\RL Adaptive Model Poisoning Attacks in FL\.venv\lib\site-packages\stable_baselines3\common\base_class.py", line 681, in load
    data, params, pytorch_variables = load_from_zip_file(
  File "C:\RL Adaptive Model Poisoning Attacks in FL\.venv\lib\site-packages\stable_baselines3\common\save_util.py", line 403, in load_from_zip_file
    file = open_path(load_path, "r", verbose=verbose, suffix="zip")
  File "C:\Program Files\WindowsApps\PythonSoftwareFoundation.Python.3.9_3.9.3568.0_x64__qbz5n2kfra8p0\lib\functools.py", line 888, in wrapper
    return dispatch(args[0].__class__)(*args, **kw)
  File "C:\RL Adaptive Model Poisoning Attacks in FL\.venv\lib\site-packages\stable_baselines3\common\save_util.py", line 240, in open_path_str
    return open_path_pathlib(pathlib.Path(path), mode, verbose, suffix)
  File "C:\RL Adaptive Model Poisoning Attacks in FL\.venv\lib\site-packages\stable_baselines3\common\save_util.py", line 291, in open_path_pathlib
    return open_path_pathlib(path, mode, verbose, suffix)
  File "C:\RL Adaptive Model Poisoning Attacks in FL\.venv\lib\site-packages\stable_baselines3\common\save_util.py", line 272, in open_path_pathlib
    raise error
  File "C:\RL Adaptive Model Poisoning Attacks in FL\.venv\lib\site-packages\stable_baselines3\common\save_util.py", line 264, in open_path_pathlib
    return open_path(path.open("rb"), mode, verbose, suffix)
  File "C:\Program Files\WindowsApps\PythonSoftwareFoundation.Python.3.9_3.9.3568.0_x64__qbz5n2kfra8p0\lib\pathlib.py", line 1252, in open
    return io.open(self, mode, buffering, encoding, errors, newline,
  File "C:\Program Files\WindowsApps\PythonSoftwareFoundation.Python.3.9_3.9.3568.0_x64__qbz5n2kfra8p0\lib\pathlib.py", line 1120, in _opener
    return self._accessor.open(self, flags, mode)
FileNotFoundError: [Errno 2] No such file or directory: 'rl_poisoning_agent.zip'

The above exception was the direct cause of the following exception:

[36mray::ClientAppActor.run()[39m (pid=38964, ip=127.0.0.1, actor_id=b010d368fd758746a05040e901000000, repr=<flwr.simulation.ray_transport.ray_actor.ClientAppActor object at 0x000002E280ABC9A0>)
  File "python\ray\_raylet.pyx", line 1890, in ray._raylet.execute_task
  File "python\ray\_raylet.pyx", line 1991, in ray._raylet.execute_task
  File "python\ray\_raylet.pyx", line 1896, in ray._raylet.execute_task
  File "python\ray\_raylet.pyx", line 1837, in ray._raylet.execute_task.function_executor
  File "C:\RL Adaptive Model Poisoning Attacks in FL\.venv\lib\site-packages\ray\_private\function_manager.py", line 691, in actor_method_executor
    return method(__ray_actor, *args, **kwargs)
  File "C:\RL Adaptive Model Poisoning Attacks in FL\.venv\lib\site-packages\ray\util\tracing\tracing_helper.py", line 467, in _resume_span
    return method(self, *_args, **_kwargs)
  File "C:\RL Adaptive Model Poisoning Attacks in FL\.venv\lib\site-packages\flwr\simulation\ray_transport\ray_actor.py", line 64, in run
    raise ClientAppException(str(ex)) from ex
flwr.client.client_app.ClientAppException: 
Exception ClientAppException occurred. Message: [Errno 2] No such file or directory: 'rl_poisoning_agent.zip'
